Workbook

Sheet AKBO Estimate
A1: AKBO Purchase - Cost Estimate
A2: Unit prices are looked up from the AKBO price list valid from 15-08-2026 ('Price List' tab), < 20 pcs tier. Blue text / yellow cells are inputs.
A4: # | B4: Requested Code | C4: Price List Code | D4: Description (from price list) | E4: Qty | F4: Unit Price (EUR, < 20 pcs) | G4: Line Total (EUR) | H4: Notes
A5: 1 | B5: AKRSV01-B | C5: AKRSV01-B | D5: =IFERROR(TRIM(CLEAN(INDEX('Price List'!$B$1:$B$259,MATCH(C5,'Price List'!$A$1:$A$259,0)))),"NOT IN PRICE LIST") | E5: 1 | F5: =IFERROR(INDEX('Price List'!$C$1:$C$259,MATCH(C5,'Price List'!$A$1:$A$259,0)),0) | G5: =E5*F5
A6: 2 | B6: AKRSHHL1-BL | C6: AKRSHHL1-BL | D6: =IFERROR(TRIM(CLEAN(INDEX('Price List'!$B$1:$B$259,MATCH(C6,'Price List'!$A$1:$A$259,0)))),"NOT IN PRICE LIST") | E6: 1 | F6: =IFERROR(INDEX('Price List'!$C$1:$C$259,MATCH(C6,'Price List'!$A$1:$A$259,0)),0) | G6: =E6*F6
A7: 3 | B7: AKRS001-B | C7: AKR001-B | D7: =IFERROR(TRIM(CLEAN(INDEX('Price List'!$B$1:$B$259,MATCH(C7,'Price List'!$A$1:$A$259,0)))),"NOT IN PRICE LIST") | E7: 1 | F7: =IFERROR(INDEX('Price List'!$C$1:$C$259,MATCH(C7,'Price List'!$A$1:$A$259,0)),0) | G7: =E7*F7 | H7: Not in price list; using AKR001-B (st. st. shower head, blue)
A8: 4 | B8: AKRSHHL4-BL | C8: AKRSHH4-BL | D8: =IFERROR(TRIM(CLEAN(INDEX('Price List'!$B$1:$B$259,MATCH(C8,'Price List'!$A$1:$A$259,0)))),"NOT IN PRICE LIST") | E8: 1 | F8: =IFERROR(INDEX('Price List'!$C$1:$C$259,MATCH(C8,'Price List'!$A$1:$A$259,0)),0) | G8: =E8*F8 | H8: Not in price list; using AKRSHH4-BL (st. st. spray head, black)
A9: 5 | B9: TWRWR02M | C9: TWRWR02M | D9: =IFERROR(TRIM(CLEAN(INDEX('Price List'!$B$1:$B$259,MATCH(C9,'Price List'!$A$1:$A$259,0)))),"NOT IN PRICE LIST") | E9: 1 | F9: =IFERROR(INDEX('Price List'!$C$1:$C$259,MATCH(C9,'Price List'!$A$1:$A$259,0)),0) | G9: =E9*F9 | H9: Listed twice in your request
A10: 6 | B10: BMFTP11-B-PRIN | C10: BMFTP11-B-PRIN | D10: =IFERROR(TRIM(CLEAN(INDEX('Price List'!$B$1:$B$259,MATCH(C10,'Price List'!$A$1:$A$259,0)))),"NOT IN PRICE LIST") | E10: 1 | F10: =IFERROR(INDEX('Price List'!$C$1:$C$259,MATCH(C10,'Price List'!$A$1:$A$259,0)),0) | G10: =E10*F10
A11: 7 | B11: AKMN001-B | C11: AKMN001-B | D11: =IFERROR(TRIM(CLEAN(INDEX('Price List'!$B$1:$B$259,MATCH(C11,'Price List'!$A$1:$A$259,0)))),"NOT IN PRICE LIST") | E11: 1 | F11: =IFERROR(INDEX('Price List'!$C$1:$C$259,MATCH(C11,'Price List'!$A$1:$A$259,0)),0) | G11: =E11*F11
A12: 8 | B12: AKNN001-B | C12: AKNN001-B | D12: =IFERROR(TRIM(CLEAN(INDEX('Price List'!$B$1:$B$259,MATCH(C12,'Price List'!$A$1:$A$259,0)))),"NOT IN PRICE LIST") | E12: 1 | F12: =IFERROR(INDEX('Price List'!$C$1:$C$259,MATCH(C12,'Price List'!$A$1:$A$259,0)),0) | G12: =E12*F12
A13: 9 | B13: BABTN01-B | C13: BABTN01-B | D13: =IFERROR(TRIM(CLEAN(INDEX('Price List'!$B$1:$B$259,MATCH(C13,'Price List'!$A$1:$A$259,0)))),"NOT IN PRICE LIST") | E13: 1 | F13: =IFERROR(INDEX('Price List'!$C$1:$C$259,MATCH(C13,'Price List'!$A$1:$A$259,0)),0) | G13: =E13*F13
A14: 10 | B14: AKRHP01-R | C14: AKRHP01-R | D14: =IFERROR(TRIM(CLEAN(INDEX('Price List'!$B$1:$B$259,MATCH(C14,'Price List'!$A$1:$A$259,0)))),"NOT IN PRICE LIST") | E14: 1 | F14: =IFERROR(INDEX('Price List'!$C$1:$C$259,MATCH(C14,'Price List'!$A$1:$A$259,0)),0) | G14: =E14*F14
A15: 11 | B15: AKKS003-B | C15: AKKS003-B | D15: =IFERROR(TRIM(CLEAN(INDEX('Price List'!$B$1:$B$259,MATCH(C15,'Price List'!$A$1:$A$259,0)))),"NOT IN PRICE LIST") | E15: 1 | F15: =IFERROR(INDEX('Price List'!$C$1:$C$259,MATCH(C15,'Price List'!$A$1:$A$259,0)),0) | G15: =E15*F15
A16: 12 | B16: AKAWLU1-B | C16: AKAWLU1-B | D16: =IFERROR(TRIM(CLEAN(INDEX('Price List'!$B$1:$B$259,MATCH(C16,'Price List'!$A$1:$A$259,0)))),"NOT IN PRICE LIST") | E16: 1 | F16: =IFERROR(INDEX('Price List'!$C$1:$C$259,MATCH(C16,'Price List'!$A$1:$A$259,0)),0) | G16: =E16*F16
A17: 13 | B17: AGIL572 | C17: AGIL572 | D17: =IFERROR(TRIM(CLEAN(INDEX('Price List'!$B$1:$B$259,MATCH(C17,'Price List'!$A$1:$A$259,0)))),"NOT IN PRICE LIST") | E17: 1 | F17: =IFERROR(INDEX('Price List'!$C$1:$C$259,MATCH(C17,'Price List'!$A$1:$A$259,0)),0) | G17: =E17*F17
A18: 14 | B18: BABTLF1-B-V | C18: BABTLF1-BL | D18: =IFERROR(TRIM(CLEAN(INDEX('Price List'!$B$1:$B$259,MATCH(C18,'Price List'!$A$1:$A$259,0)))),"NOT IN PRICE LIST") | E18: 1 | F18: =IFERROR(INDEX('Price List'!$C$1:$C$259,MATCH(C18,'Price List'!$A$1:$A$259,0)),0) | G18: =E18*F18 | H18: Not in price list; closest is BABTLF1-BL (black) - confirm blue/Viton price with AKBO
A19: 15 | B19: AKWMM01 | C19: AKWMM01 | D19: =IFERROR(TRIM(CLEAN(INDEX('Price List'!$B$1:$B$259,MATCH(C19,'Price List'!$A$1:$A$259,0)))),"NOT IN PRICE LIST") | E19: 1 | F19: =IFERROR(INDEX('Price List'!$C$1:$C$259,MATCH(C19,'Price List'!$A$1:$A$259,0)),0) | G19: =E19*F19
A20: 16 | B20: WRWR02XL | C20: TWRWR02XL | D20: =IFERROR(TRIM(CLEAN(INDEX('Price List'!$B$1:$B$259,MATCH(C20,'Price List'!$A$1:$A$259,0)))),"NOT IN PRICE LIST") | E20: 1 | F20: =IFERROR(INDEX('Price List'!$C$1:$C$259,MATCH(C20,'Price List'!$A$1:$A$259,0)),0) | G20: =E20*F20 | H20: Assumed typo for TWRWR02XL (Twister XL)
A21: 17 | B21: TWRWR02L | C21: TWRWR02L | D21: =IFERROR(TRIM(CLEAN(INDEX('Price List'!$B$1:$B$259,MATCH(C21,'Price List'!$A$1:$A$259,0)))),"NOT IN PRICE LIST") | E21: 1 | F21: =IFERROR(INDEX('Price List'!$C$1:$C$259,MATCH(C21,'Price List'!$A$1:$A$259,0)),0) | G21: =E21*F21
A22: 18 | B22: TWRWR02M | C22: TWRWR02M | D22: =IFERROR(TRIM(CLEAN(INDEX('Price List'!$B$1:$B$259,MATCH(C22,'Price List'!$A$1:$A$259,0)))),"NOT IN PRICE LIST") | E22: 1 | F22: =IFERROR(INDEX('Price List'!$C$1:$C$259,MATCH(C22,'Price List'!$A$1:$A$259,0)),0) | G22: =E22*F22 | H22: Listed twice in your request
A23: 19 | B23: SWIFB13-C17 | C23: SWIFB13-C17 | D23: =IFERROR(TRIM(CLEAN(INDEX('Price List'!$B$1:$B$259,MATCH(C23,'Price List'!$A$1:$A$259,0)))),"NOT IN PRICE LIST") | E23: 1 | F23: =IFERROR(INDEX('Price List'!$C$1:$C$259,MATCH(C23,'Price List'!$A$1:$A$259,0)),0) | G23: =E23*F23
A24: 20 | B24: SWIFB19-C24 | C24: SWIFB19-C24 | D24: =IFERROR(TRIM(CLEAN(INDEX('Price List'!$B$1:$B$259,MATCH(C24,'Price List'!$A$1:$A$259,0)))),"NOT IN PRICE LIST") | E24: 1 | F24: =IFERROR(INDEX('Price List'!$C$1:$C$259,MATCH(C24,'Price List'!$A$1:$A$259,0)),0) | G24: =E24*F24
A25: 21 | B25: SWIFB19-C24-34 | C25: SWIFB19-C24-34 | D25: =IFERROR(TRIM(CLEAN(INDEX('Price List'!$B$1:$B$259,MATCH(C25,'Price List'!$A$1:$A$259,0)))),"NOT IN PRICE LIST") | E25: 1 | F25: =IFERROR(INDEX('Price List'!$C$1:$C$259,MATCH(C25,'Price List'!$A$1:$A$259,0)),0) | G25: =E25*F25
F27: Lines | G27: =COUNTA(B5:B25)
F28: Total qty | G28: =SUM(E5:E25)
F29: Subtotal (EUR, ex VAT) | G29: =SUM(G5:G25)
F30: Freight / shipping (EUR)
F31: Total (EUR) | G31: =G29+G30
F33: Exchange rate (NZD per 1 EUR)
F34: Total (NZD, before GST/duty) | G34: =G31*G33
F35: NZ GST rate on import | G35: 0.15
F36: GST (NZD) | G36: =G34*G35
F37: Estimated landed total (NZD incl GST) | G37: =G34+G36
A39: Notes
A40: - Source: AKBO price list for Nozzleworks NZL (washdown guns), valid from 15-08-2026. Prices in EUR per piece, < 20 pcs tier (qty 1 each).
A41: - Green prices are looked up from the 'Price List' tab by Price List Code. Change a code in column C to re-price that line.
A42: - Three requested codes are not in the price list and use the closest match (see Notes column). WRWR02XL is treated as TWRWR02XL.
A43: - TWRWR02M appears twice in the original list, so it is included twice. Delete one row if that was unintended.
A44: - Customs duty, import fees and brokerage are not included.

Sheet Price List
A1: PRICE LIST, VALID FROM 15-08-2026
A2: Due to rounding differences, some prices in this price list may differ slightly (typically ±€0.01) from the prices invoiced from our system.
A5: Heavy duty spray guns
A7: Product code | B7: Description | C7: Price p/pc in Euro
C8: < 20 pcs | D8: ≥ 20 pcs | E8: ≥ 50 pcs
D9: 0.1 | E9: 0.2
A10: AKNN001-B | B10: Water gun with glass reinforced PA66 blue body. Stainless shaft with EPDM and VITON O-ring | C10: 29.74 | D10: 26.43
A11: BMFT001-B | B11: Blue Princess economic brass water gun, blue | C11: 22.47399 | D11: 19.97688
A12: BMFT001-B-PRIN | B12: Blue Princess economic brass water gun, blue with PRINCESS logo | C12: 22.52052 | D12: 20.01824
A13: BMFTP11-B-PRIN | B13: Princess economic brass water gun with trigger guard and trigger insulation, blue with PRINCESS logo | C13: 30.38409 | D13: 27.00808
A14: KLMN001-B | B14: Brass water gun, without trigger insulation, blue | C14: 28.14 | D14: 25.02
A15: KLMN001-R | B15: Brass water gun without trigger insulation, red | C15: 29.08 | D15: 25.85
A16: KLMN001-G | B16: Brass water gun, without trigger insulation, green | C16: 29.08 | D16: 25.85
A17: KLMN001-BL | B17: Brass water gun, without trigger insulation, black | C17: 29.08 | D17: 25.85
A18: KLMN001-Y | B18: Brass water gun, without trigger insulation, yellow | C18: 29.08 | D18: 25.85
A19: KLMN001-W | B19: Brass water gun, without trigger insulation, white | C19: 29.08 | D19: 25.85
A21: AKMN001-B | B21: Brass water gun, blue | C21: 29.24 | D21: 25.99
A22: AKMN001-R | B22: Brass water gun, red | C22: 30.17 | D22: 26.82
... A57: AKRN002-LB-LAT | B57: St.st. water gun with latex cover, light blue | C57: 114.55686 | D57: 101.83
A59: AKRSV01-B | B59: Versatile stainless steel squeeze valve "Squeezer", blue | C59: 63.12 | D59: 59.41 | E59: 51.98
A60: AKR001-B | B60: St, st. shower head, blue | C60: 18.28 | D60: 17.2 | E60: 15.05
A65: Baby water guns
A67: Product code | B67: Description | C67: Price p/pc in Euro
C68: < 20 pcs | D68: ≥ 20 pcs
A69: Baby water guns "aluminium" | D69: 0.1 | E69: 0.2
A71: BABTN01-B | B71: Aluminium "baby" water gun, back trigger, blue | C71: 19.458846 | D71: 17.296752
A72: BABTLF1-BL | B72: Aluminium "baby" water gun, back trigger, 1/2" female outlet, black | C72: 20.56626 | D72: 18.28112
A73: BABTA01-B | B73: Aluminium "baby" water gun, back trigger, adapter outlet, blue | C73: 20.56626 | D73: 18.28112
A74: BABTNAA-B | B74: Aluminium "baby" water gun, back trigger, adapter in/output, blue | C74: 22.7997 | D74: 20.2664
A77: Baby water guns "brass"
A79: BMBTN01-B | B79: Brass "baby" water gun, back trigger, blue | C79: 22.418154 | D79: 19.927248
A80: BMBNN01-B | B80: Brass "baby" water gun, back trigger, 1/2" male outlet with adjustable spray pattern, blue | C80: 22.418154 | D80: 19.927248
A81: BMBTL01-B | B81: Brass "baby" water gun, back trigger, 1/2" male outlet, blue | C81: 23.516262 | D81: 20.903344
A82: BMBTA01-B | B82: Brass "baby" water gun, back trigger, adapter output, blue | C82: 23.516262 | D82: 20.903344
A83: BMBTA02-B-V | B83: Brass "baby" water gun, back trigger, adapter output, viton seals, blue | C83: 23.516262 | D83: 20.903344
A85: Other water guns
A87: Product code | B87: Description | C87: Price p/pc in Euro
C88: < 10 pcs | D88: ≥ 10 pcs | E88: ≥ 50 pcs
D89: 0.2 | E89: 0.3
A90: AGIL572 | B90: Water nozzle light duty, red | C90: 11.19 | E90: 48pcs 9,87
...
