Workbook

Sheet Pricelist
A1: NOZZLEWORKS PRICELIST - AKBO / ARBO WASHDOWN GUNS & FITTINGS
A2: Built from AKBO price list "PRICE LIST, VALID FROM 15-08-2026". Item order and quantity breaks follow AKBO's list. Prices NZD, GST exclusive.
A4: INPUTS (edit yellow cells)
A5: Exchange rate (EUR per 1 NZD) | C5: 0.46 | D5: Per Andrew 28-Sep-2026 - to be reviewed. NZD cost = EUR / rate. | L5: Items listed | M5: =COUNT(F14:F242)
A6: Freight rate (NZD per kg) | C6: 30 | D6: Per Andrew 28-Sep-2026 - placeholder, to be updated. | L6: No NW part no. | M6: =COUNTIF(B14:B242,"NOT ASSIGNED")
A7: Volumetric weight factor (% on net weight) | C7: 0.25 | D7: Per Andrew 30-Sep-2026 - freight kg = net weight x (1 + factor). | L7: Estimated weights | M7: =COUNTIF(E14:E242,"ESTIMATE*")
A8: Tax / duty allowance (% of product cost) | C8: 0.01 | D8: Per Andrew 28-Sep-2026 - 1% on NZD product cost.
A9: List price markup (% on landed cost) | C9: 3.5 | D9: Per Andrew 30-Sep-2026 - 350% default, to be reviewed. List = landed x (1 + markup).
A10: Landed cost / pc = EUR price / FX x (1 + duty) + net weight kg x (1 + volumetric factor) x freight rate. List price / pc = landed cost x (1 + markup %).
A11: Legend: red Nozzleworks Part No = no NW part number assigned yet | amber weight = ESTIMATE, not printed in AKBO 2026 catalogue | blank price = AKBO gives no price at that break
A13: AKBO Product code | B13: Nozzleworks Part No | C13: Description | D13: Net weight (kg) | E13: Weight source | F13: Supplier price EUR / pc | I13: Landed cost NZD / pc | L13: List price NZD / pc (ex GST) | O13: Flags / notes
A15: Heavy duty spray guns
A17: Qty break | F17: < 20 pcs | G17: ≥ 20 pcs | H17: ≥ 50 pcs | I17: < 20 pcs | J17: ≥ 20 pcs | K17: ≥ 50 pcs | L17: < 20 pcs | M17: ≥ 20 pcs | N17: ≥ 50 pcs
A18: AKNN001-B | B18: =IFERROR(INDEX(Conversion!$C$2:$C$500,MATCH($A18,Conversion!$B$2:$B$500,0)),"NOT ASSIGNED") | C18: Water gun with glass reinforced PA66 blue body. Stainless shaft with EPDM and VITON O-ring | D18: 0.48 | E18: Cat p.16/17 | F18: 29.74 | G18: 26.43 | I18: =IF(F18="","",F18/$C$5*(1+$C$8)+$D18*(1+$C$7)*$C$6) | J18: =IF(G18="","",G18/$C$5*(1+$C$8)+$D18*(1+$C$7)*$C$6) | K18: =IF(H18="","",H18/$C$5*(1+$C$8)+$D18*(1+$C$7)*$C$6) | L18: =IF(I18="","",ROUND(I18*(1+$C$9),2)) | M18: =IF(J18="","",ROUND(J18*(1+$C$9),2)) | N18: =IF(K18="","",ROUND(K18*(1+$C$9),2)) | O18: =TRIM(IF($B18="NOT ASSIGNED","No NW part no. ","")&IFERROR(IF(INDEX(Conversion!$J$2:$J$500,MATCH($A18,Conversion!$B$2:$B$500,0))="Needs review","Conversion table: needs review. ",""),"")&IF(LEFT($E18,8)="ESTIMATE","Weight estimated. ","")&"")
A19: BMFT001-B | B19: =IFERROR(INDEX(Conversion!$C$2:$C$500,MATCH($A19,Conversion!$B$2:$B$500,0)),"NOT ASSIGNED") | C19: Blue Princess economic brass water gun, blue | D19: 0.463 | E19: Cat p.C (Blue Princess) | F19: 22.47399 | G19: 19.97688 | I19: =IF(F19="","",F19/$C$5*(1+$C$8)+$D19*(1+$C$7)*$C$6) | J19: =IF(G19="","",G19/$C$5*(1+$C$8)+$D19*(1+$C$7)*$C$6) | K19: =IF(H19="","",H19/$C$5*(1+$C$8)+$D19*(1+$C$7)*$C$6) | L19: =IF(I19="","",ROUND(I19*(1+$C$9),2)) | M19: =IF(J19="","",ROUND(J19*(1+$C$9),2)) | N19: =IF(K19="","",ROUND(K19*(1+$C$9),2)) | O19: =TRIM(IF($B19="NOT ASSIGNED","No NW part no. ","")&IFERROR(IF(INDEX(Conversion!$J$2:$J$500,MATCH($A19,Conversion!$B$2:$B$500,0))="Needs review","Conversion table: needs review. ",""),"")&IF(LEFT($E19,8)="ESTIMATE","Weight estimated. ","")&"")
A20: BMFT001-B-PRIN | B20: =IFERROR(INDEX(Conversion!$C$2:$C$500,MATCH($A20,Conversion!$B$2:$B$500,0)),"NOT ASSIGNED") | C20: Blue Princess economic brass water gun, blue with PRINCESS logo | D20: 0.463 | E20: Cat p.C - same gun as BMFT001-B, logo only | F20: 22.52052 | G20: 20.01824 | I20: =IF(F20="","",F20/$C$5*(1+$C$8)+$D20*(1+$C$7)*$C$6) | J20: =IF(G20="","",G20/$C$5*(1+$C$8)+$D20*(1+$C$7)*$C$6) | K20: =IF(H20="","",H20/$C$5*(1+$C$8)+$D20*(1+$C$7)*$C$6) | L20: =IF(I20="","",ROUND(I20*(1+$C$9),2)) | M20: =IF(J20="","",ROUND(J20*(1+$C$9),2)) | N20: =IF(K20="","",ROUND(K20*(1+$C$9),2)) | O20: =TRIM(IF($B20="NOT ASSIGNED","No NW part no. ","")&IFERROR(IF(INDEX(Conversion!$J$2:$J$500,MATCH($A20,Conversion!$B$2:$B$500,0))="Needs review","Conversion table: needs review. ",""),"")&IF(LEFT($E20,8)="ESTIMATE","Weight estimated. ","")&"")
A21: BMFTP11-B-PRIN | B21: =IFERROR(INDEX(Conversion!$C$2:$C$500,MATCH($A21,Conversion!$B$2:$B$500,0)),"NOT ASSIGNED") | C21: Princess economic brass water gun with trigger guard and trigger insulation, blue with PRINCESS logo | D21: 0.59 | E21: Cat p.C | F21: 30.38409 | G21: 27.00808 | I21: =IF(F21="","",F21/$C$5*(1+$C$8)+$D21*(1+$C$7)*$C$6) | J21: =IF(G21="","",G21/$C$5*(1+$C$8)+$D21*(1+$C$7)*$C$6) | K21: =IF(H21="","",H21/$C$5*(1+$C$8)+$D21*(1+$C$7)*$C$6) | L21: =IF(I21="","",ROUND(I21*(1+$C$9),2)) | M21: =IF(J21="","",ROUND(J21*(1+$C$9),2)) | N21: =IF(K21="","",ROUND(K21*(1+$C$9),2)) | O21: =TRIM(IF($B21="NOT ASSIGNED","No NW part no. ","")&IFERROR(IF(INDEX(Conversion!$J$2:$J$500,MATCH($A21,Conversion!$B$2:$B$500,0))="Needs review","Conversion table: needs review. ",""),"")&IF(LEFT($E21,8)="ESTIMATE","Weight estimated. ","")&"")
A22: KLMN001-B | B22: =IFERROR(INDEX(Conversion!$C$2:$C$500,MATCH($A22,Conversion!$B$2:$B$500,0)),"NOT ASSIGNED") | C22: Brass water gun, without trigger insulation, blue | D22: 0.84 | E22: Cat p.9 | F22: 28.14 | G22: 25.02 | I22: =IF(F22="","",F22/$C$5*(1+$C$8)+$D22*(1+$C$7)*$C$6) | J22: =IF(G22="","",G22/$C$5*(1+$C$8)+$D22*(1+$C$7)*$C$6) | K22: =IF(H22="","",H22/$C$5*(1+$C$8)+$D22*(1+$C$7)*$C$6) | L22: =IF(I22="","",ROUND(I22*(1+$C$9),2)) | M22: =IF(J22="","",ROUND(J22*(1+$C$9),2)) | N22: =IF(K22="","",ROUND(K22*(1+$C$9),2)) | O22: =TRIM(IF($B22="NOT ASSIGNED","No NW part no. ","")&IFERROR(IF(INDEX(Conversion!$J$2:$J$500,MATCH($A22,Conversion!$B$2:$B$500,0))="Needs review","Conversion table: needs review. ",""),"")&IF(LEFT($E22,8)="ESTIMATE","Weight estimated. ","")&"")
A23: KLMN001-R | B23: =IFERROR(INDEX(Conversion!$C$2:$C$500,MATCH($A23,Conversion!$B$2:$B$500,0)),"NOT ASSIGNED") | C23: Brass water gun without trigger insulation, red | D23: 0.84 | E23: Cat p.9 | F23: 29.08 | G23: 25.85 | I23: =IF(F23="","",F23/$C$5*(1+$C$8)+$D23*(1+$C$7)*$C$6) | J23: =IF(G23="","",G23/$C$5*(1+$C$8)+$D23*(1+$C$7)*$C$6) | K23: =IF(H23="","",H23/$C$5*(1+$C$8)+$D23*(1+$C$7)*$C$6) | L23: =IF(I23="","",ROUND(I23*(1+$C$9),2)) | M23: =IF(J23="","",ROUND(J23*(1+$C$9),2)) | N23: =IF(K23="","",ROUND(K23*(1+$C$9),2)) | O23: =TRIM(IF($B23="NOT ASSIGNED","No NW part no. ","")&IFERROR(IF(INDEX(Conversion!$J$2:$J$500,MATCH($A23,Conversion!$B$2:$B$500,0))="Needs review","Conversion table: needs review. ",""),"")&IF(LEFT($E23,8)="ESTIMATE","Weight estimated. ","")&"")
A24: KLMN001-G | B24: =IFERROR(INDEX(Conversion!$C$2:$C$500,MATCH($A24,Conversion!$B$2:$B$500,0)),"NOT ASSIGNED") | C24: Brass water gun, without trigger insulation, green | D24: 0.84 | E24: Cat p.9 | F24: 29.08 | G24: 25.85 | I24: =IF(F24="","",F24/$C$5*(1+$C$8)+$D24*(1+$C$7)*$C$6) | J24: =IF(G24="","",G24/$C$5*(1+$C$8)+$D24*(1+$C$7)*$C$6) | K24: =IF(H24="","",H24/$C$5*(1+$C$8)+$D24*(1+$C$7)*$C$6) | L24: =IF(I24="","",ROUND(I24*(1+$C$9),2)) | M24: =IF(J24="","",ROUND(J24*(1+$C$9),2)) | N24: =IF(K24="","",ROUND(K24*(1+$C$9),2)) | O24: =TRIM(IF($B24="NOT ASSIGNED","No NW part no. ","")&IFERROR(IF(INDEX(Conversion!$J$2:$J$500,MATCH($A24,Conversion!$B$2:$B$500,0))="Needs review","Conversion table: needs review. ",""),"")&IF(LEFT($E24,8)="ESTIMATE","Weight estimated. ","")&"")
A25: KLMN001-BL | B25: =IFERROR(INDEX(Conversion!$C$2:$C$500,MATCH($A25,Conversion!$B$2:$B$500,0)),"NOT ASSIGNED") | C25: Brass water gun, without trigger insulation, black | D25: 0.84 | E25: Cat p.9 | F25: 29.08 | G25: 25.85 | I25: =IF(F25="","",F25/$C$5*(1+$C$8)+$D25*(1+$C$7)*$C$6) | J25: =IF(G25="","",G25/$C$5*(1+$C$8)+$D25*(1+$C$7)*$C$6) | K25: =IF(H25="","",H25/$C$5*(1+$C$8)+$D25*(1+$C$7)*$C$6) | L25: =IF(I25="","",ROUND(I25*(1+$C$9),2)) | M25: =IF(J25="","",ROUND(J25*(1+$C$9),2)) | N25: =IF(K25="","",ROUND(K25*(1+$C$9),2)) | O25: =TRIM(IF($B25="NOT ASSIGNED","No NW part no. ","")&IFERROR(IF(INDEX(Conversion!$J$2:$J$500,MATCH($A25,Conversion!$B$2:$B$500,0))="Needs review","Conversion table: needs review. ",""),"")&IF(LEFT($E25,8)="ESTIMATE","Weight estimated. ","")&"")
A26: KLMN001-Y | B26: =IFERROR(INDEX(Conversion!$C$2:$C$500,MATCH($A26,Conversion!$B$2:$B$500,0)),"NOT ASSIGNED") | C26: Brass water gun, without trigger insulation, yellow | D26: 0.84 | E26: Cat p.9 | F26: 29.08 | G26: 25.85 | I26: =IF(F26="","",F26/$C$5*(1+$C$8)+$D26*(1+$C$7)*$C$6) | J26: =IF(G26="","",G26/$C$5*(1+$C$8)+$D26*(1+$C$7)*$C$6) | K26: =IF(H26="","",H26/$C$5*(1+$C$8)+$D26*(1+$C$7)*$C$6) | L26: =IF(I26="","",ROUND(I26*(1+$C$9),2)) | M26: =IF(J26="","",ROUND(J26*(1+$C$9),2)) | N26: =IF(K26="","",ROUND(K26*(1+$C$9),2)) | O26: =TRIM(IF($B26="NOT ASSIGNED","No NW part no. ","")&IFERROR(IF(INDEX(Conversion!$J$2:$J$500,MATCH($A26,Conversion!$B$2:$B$500,0))="Needs review","Conversion table: needs review. ",""),"")&IF(LEFT($E26,8)="ESTIMATE","Weight estimated. ","")&"")
A27: KLMN001-W | B27: =IFERROR(INDEX(Conversion!$C$2:$C$500,MATCH($A27,Conversion!$B$2:$B$500,0)),"NOT ASSIGNED") | C27: Brass water gun, without trigger insulation, white | D27: 0.84 | E27: Cat p.9 | F27: 29.08 | G27: 25.85 | I27: =IF(F27="","",F27/$C$5*(1+$C$8)+$D27*(1+$C$7)*$C$6) | J27: =IF(G27="","",G27/$C$5*(1+$C$8)+$D27*(1+$C$7)*$C$6) | K27: =IF(H27="","",H27/$C$5*(1+$C$8)+$D27*(1+$C$7)*$C$6) | L27: =IF(I27="","",ROUND(I27*(1+$C$9),2)) | M27: =IF(J27="","",ROUND(J27*(1+$C$9),2)) | N27: =IF(K27="","",ROUND(K27*(1+$C$9),2)) | O27: =TRIM(IF($B27="NOT ASSIGNED","No NW part no. ","")&IFERROR(IF(INDEX(Conversion!$J$2:$J$500,MATCH($A27,Conversion!$B$2:$B$500,0))="Needs review","Conversion table: needs review. ",""),"")&IF(LEFT($E27,8)="ESTIMATE","Weight estimated. ","")&"")
A29: AKMN001-B | B29: =IFERROR(INDEX(Conversion!$C$2:$C$500,MATCH($A29,Conversion!$B$2:$B$500,0)),"NOT ASSIGNED") | C29: Brass water gun, blue | D29: 0.835 | E29: Cat p.11 | F29: 29.24 | G29: 25.99 | I29: =IF(F29="","",F29/$C$5*(1+$C$8)+$D29*(1+$C$7)*$C$6) | J29: =IF(G29="","",G29/$C$5*(1+$C$8)+$D29*(1+$C$7)*$C$6) | K29: =IF(H29="","",H29/$C$5*(1+$C$8)+$D29*(1+$C$7)*$C$6) | L29: =IF(I29="","",ROUND(I29*(1+$C$9),2)) | M29: =IF(J29="","",ROUND(J29*(1+$C$9),2)) | N29: =IF(K29="","",ROUND(K29*(1+$C$9),2)) | O29: =TRIM(IF($B29="NOT ASSIGNED","No NW part no. ","")&IFERROR(IF(INDEX(Conversion!$J$2:$J$500,MATCH($A29,Conversion!$B$2:$B$500,0))="Needs review","Conversion table: needs review. ",""),"")&IF(LEFT($E29,8)="ESTIMATE","Weight estimated. ","")&"")
A30: AKMN001-R | B30: =IFERROR(INDEX(Conversion!$C$2:$C$500,MATCH($A30,Conversion!$B$2:$B$500,0)),"NOT ASSIGNED") | C30: Brass water gun, red | D30: 0.835 | E30: Cat p.11 | F30: 30.17 | G30: 26.82 | I30: =IF(F30="","",F30/$C$5*(1+$C$8)+$D30*(1+$C$7)*$C$6) | J30: =IF(G30="","",G30/$C$5*(1+$C$8)+$D30*(1+$C$7)*$C$6) | K30: =IF(H30="","",H30/$C$5*(1+$C$8)+$D30*(1+$C$7)*$C$6) | L30: =IF(I30="","",ROUND(I30*(1+$C$9),2)) | M30: =IF(J30="","",ROUND(J30*(1+$C$9),2)) | N30: =IF(K30="","",ROUND(K30*(1+$C$9),2)) | O30: =TRIM(IF($B30="NOT ASSIGNED","No NW part no. ","")&IFERROR(IF(INDEX(Conversion!$J$2:$J$500,MATCH($A30,Conversion!$B$2:$B$500,0))="Needs review","Conversion table: needs review. ",""),"")&IF(LEFT($E30,8)="ESTIMATE","Weight estimated. ","")&"")
... A44: AKMB001-BL | B44: =IFERROR(INDEX(Conversion!$C$2:$C$500,MATCH($A44,Conversion!$B$2:$B$500,0)),"NOT ASSIGNED") | C44: Brass water gun, big flow, black | D44: 0.84 | E44: Cat p.20 | F44: 36.4485 | G44: 32.81 | I44: =IF(F44="","",F44/$C$5*(1+$C$8)+$D44*(1+$C$7)*$C$6) | J44: =IF(G44="","",G44/$C$5*(1+$C$8)+$D44*(1+$C$7)*$C$6) | K44: =IF(H44="","",H44/$C$5*(1+$C$8)+$D44*(1+$C$7)*$C$6) | L44: =IF(I44="","",ROUND(I44*(1+$C$9),2)) | M44: =IF(J44="","",ROUND(J44*(1+$C$9),2)) | N44: =IF(K44="","",ROUND(K44*(1+$C$9),2)) | O44: =TRIM(IF($B44="NOT ASSIGNED","No NW part no. ","")&IFERROR(IF(INDEX(Conversion!$J$2:$J$500,MATCH($A44,Conversion!$B$2:$B$500,0))="Needs review","Conversion table: needs review. ",""),"")&IF(LEFT($E44,8)="ESTIMATE","Weight estimated. ","")&"")
A45: AKMBP01-BL | B45: =IFERROR(INDEX(Conversion!$C$2:$C$500,MATCH($A45,Conversion!$B$2:$B$500,0)),"NOT ASSIGNED") | C45: Brass water gun, big flow, with trigger protection, black | D45: 1.036 | E45: ESTIMATE - not tabulated; AKMB001-BL + trigger guard (AKMN delta) | F45: 38.88874 | G45: 35 | I45: =IF(F45="","",F45/$C$5*(1+$C$8)+$D45*(1+$C$7)*$C$6) | J45: =IF(G45="","",G45/$C$5*(1+$C$8)+$D45*(1+$C$7)*$C$6) | K45: =IF(H45="","",H45/$C$5*(1+$C$8)+$D45*(1+$C$7)*$C$6) | L45: =IF(I45="","",ROUND(I45*(1+$C$9),2)) | M45: =IF(J45="","",ROUND(J45*(1+$C$9),2)) | N45: =IF(K45="","",ROUND(K45*(1+$C$9),2)) | O45: =TRIM(IF($B45="NOT ASSIGNED","No NW part no. ","")&IFERROR(IF(INDEX(Conversion!$J$2:$J$500,MATCH($A45,Conversion!$B$2:$B$500,0))="Needs review","Conversion table: needs review. ",""),"")&IF(LEFT($E45,8)="ESTIMATE","Weight estimated. ","")&"Catalogue only lists AKMBP01-B-SWM14-3/4 (with swivel) - confirm model.")
A46: AKRB001-BL | B46: =IFERROR(INDEX(Conversion!$C$2:$C$500,MATCH($A46,Conversion!$B$2:$B$500,0)),"NOT ASSIGNED") | C46: Stainless steel water gun, high flow, black | D46: 0.84 | E46: ESTIMATE - not tabulated; taken as AKMB001-BL | F46: 84.8 | G46: 75.38 | I46: =IF(F46="","",F46/$C$5*(1+$C$8)+$D46*(1+$C$7)*$C$6) | J46: =IF(G46="","",G46/$C$5*(1+$C$8)+$D46*(1+$C$7)*$C$6) | K46: =IF(H46="","",H46/$C$5*(1+$C$8)+$D46*(1+$C$7)*$C$6) | L46: =IF(I46="","",ROUND(I46*(1+$C$9),2)) | M46: =IF(J46="","",ROUND(J46*(1+$C$9),2)) | N46: =IF(K46="","",ROUND(K46*(1+$C$9),2)) | O46: =TRIM(IF($B46="NOT ASSIGNED","No NW part no. ","")&IFERROR(IF(INDEX(Conversion!$J$2:$J$500,MATCH($A46,Conversion!$B$2:$B$500,0))="Needs review","Conversion table: needs review. ",""),"")&IF(LEFT($E46,8)="ESTIMATE","Weight estimated. ","")&"")
A48: AKCN001-B | B48: =IFERROR(INDEX(Conversion!$C$2:$C$500,MATCH($A48,Conversion!$B$2:$B$500,0)),"NOT ASSIGNED") | C48: Chrome plated brass water gun, blue | D48: 0.867 | E48: Cat p.13 | F48: 36.69 | G48: 32.62 | I48: =IF(F48="","",F48/$C$5*(1+$C$8)+$D48*(1+$C$7)*$C$6) | J48: =IF(G48="","",G48/$C$5*(1+$C$8)+$D48*(1+$C$7)*$C$6) | K48: =IF(H48="","",H48/$C$5*(1+$C$8)+$D48*(1+$C$7)*$C$6) | L48: =IF(I48="","",ROUND(I48*(1+$C$9),2)) | M48: =IF(J48="","",ROUND(J48*(1+$C$9),2)) | N48: =IF(K48="","",ROUND(K48*(1+$C$9),2)) | O48: =TRIM(IF($B48="NOT ASSIGNED","No NW part no. ","")&IFERROR(IF(INDEX(Conversion!$J$2:$J$500,MATCH($A48,Conversion!$B$2:$B$500,0))="Needs review","Conversion table: needs review. ",""),"")&IF(LEFT($E48,8)="ESTIMATE","Weight estimated. ","")&"")
A49: AKCNP01-B | B49: =IFERROR(INDEX(Conversion!$C$2:$C$500,MATCH($A49,Conversion!$B$2:$B$500,0)),"NOT ASSIGNED") | C49: Chrome plated brass water gun, with trigger protection, blue | D49: 1.016 | E49: Cat p.13 | F49: 38.93 | G49: 34.6 | I49: =IF(F49="","",F49/$C$5*(1+$C$8)+$D49*(1+$C$7)*$C$6) | J49: =IF(G49="","",G49/$C$5*(1+$C$8)+$D49*(1+$C$7)*$C$6) | K49: =IF(H49="","",H49/$C$5*(1+$C$8)+$D49*(1+$C$7)*$C$6) | L49: =IF(I49="","",ROUND(I49*(1+$C$9),2)) | M49: =IF(J49="","",ROUND(J49*(1+$C$9),2)) | N49: =IF(K49="","",ROUND(K49*(1+$C$9),2)) | O49: =TRIM(IF($B49="NOT ASSIGNED","No NW part no. ","")&IFERROR(IF(INDEX(Conversion!$J$2:$J$500,MATCH($A49,Conversion!$B$2:$B$500,0))="Needs review","Conversion table: needs review. ",""),"")&IF(LEFT($E49,8)="ESTIMATE","Weight estimated. ","")&"")
A50: AKCNP01-W | B50: =IFERROR(INDEX(Conversion!$C$2:$C$500,MATCH($A50,Conversion!$B$2:$B$500,0)),"NOT ASSIGNED") | C50: Chrome plated brass water gun, with trigger protection, white | D50: 1.016 | E50: Cat p.13 | F50: 38.93 | G50: 34.6 | I50: =IF(F50="","",F50/$C$5*(1+$C$8)+$D50*(1+$C$7)*$C$6) | J50: =IF(G50="","",G50/$C$5*(1+$C$8)+$D50*(1+$C$7)*$C$6) | K50: =IF(H50="","",H50/$C$5*(1+$C$8)+$D50*(1+$C$7)*$C$6) | L50: =IF(I50="","",ROUND(I50*(1+$C$9),2)) | M50: =IF(J50="","",ROUND(J50*(1+$C$9),2)) | N50: =IF(K50="","",ROUND(K50*(1+$C$9),2)) | O50: =TRIM(IF($B50="NOT ASSIGNED","No NW part no. ","")&IFERROR(IF(INDEX(Conversion!$J$2:$J$500,MATCH($A50,Conversion!$B$2:$B$500,0))="Needs review","Conversion table: needs review. ",""),"")&IF(LEFT($E50,8)="ESTIMATE","Weight estimated. ","")&"")
A52: BRFT003-B | B52: =IFERROR(INDEX(Conversion!$C$2:$C$500,MATCH($A52,Conversion!$B$2:$B$500,0)),"NOT ASSIGNED") | C52: Blue Princess economic stainless steel water gun, blue | D52: 0.48 | E52: Cat p.C | F52: 55.165968 | G52: 49.036416 | I52: =IF(F52="","",F52/$C$5*(1+$C$8)+$D52*(1+$C$7)*$C$6) | J52: =IF(G52="","",G52/$C$5*(1+$C$8)+$D52*(1+$C$7)*$C$6) | K52: =IF(H52="","",H52/$C$5*(1+$C$8)+$D52*(1+$C$7)*$C$6) | L52: =IF(I52="","",ROUND(I52*(1+$C$9),2)) | M52: =IF(J52="","",ROUND(J52*(1+$C$9),2)) | N52: =IF(K52="","",ROUND(K52*(1+$C$9),2)) | O52: =TRIM(IF($B52="NOT ASSIGNED","No NW part no. ","")&IFERROR(IF(INDEX(Conversion!$J$2:$J$500,MATCH($A52,Conversion!$B$2:$B$500,0))="Needs review","Conversion table: needs review. ",""),"")&IF(LEFT($E52,8)="ESTIMATE","Weight estimated. ","")&"")
A53: BRFT003-B-PRIN | B53: =IFERROR(INDEX(Conversion!$C$2:$C$500,MATCH($A53,Conversion!$B$2:$B$500,0)),"NOT ASSIGNED") | C53: Blue Princess economic stainless steel water gun, blue with PRINCESS logo | D53: 0.48 | E53: Cat p.C - same gun as BRFT003-B, logo only | F53: 55.212498 | G53: 49.077776 | I53: =IF(F53="","",F53/$C$5*(1+$C$8)+$D53*(1+$C$7)*$C$6) | J53: =IF(G53="","",G53/$C$5*(1+$C$8)+$D53*(1+$C$7)*$C$6) | K53: =IF(H53="","",H53/$C$5*(1+$C$8)+$D53*(1+$C$7)*$C$6) | L53: =IF(I53="","",ROUND(I53*(1+$C$9),2)) | M53: =IF(J53="","",ROUND(J53*(1+$C$9),2)) | N53: =IF(K53="","",ROUND(K53*(1+$C$9),2)) | O53: =TRIM(IF($B53="NOT ASSIGNED","No NW part no. ","")&IFERROR(IF(INDEX(Conversion!$J$2:$J$500,MATCH($A53,Conversion!$B$2:$B$500,0))="Needs review","Conversion table: needs review. ",""),"")&IF(LEFT($E53,8)="ESTIMATE","Weight estimated. ","")&"")
A54: BRFTP03-B-PRIN | B54: =IFERROR(INDEX(Conversion!$C$2:$C$500,MATCH($A54,Conversion!$B$2:$B$500,0)),"NOT ASSIGNED") | C54: Blue Princess economic stainless steel water gun, with trigger guard and insulation trigger, bue with Princess logo | D54: 0.62 | E54: Cat p.C (catalogue code BRFTP13-B-PRIN) | F54: 71.127 | G54: 63.224 | I54: =IF(F54="","",F54/$C$5*(1+$C$8)+$D54*(1+$C$7)*$C$6) | J54: =IF(G54="","",G54/$C$5*(1+$C$8)+$D54*(1+$C$7)*$C$6) | K54: =IF(H54="","",H54/$C$5*(1+$C$8)+$D54*(1+$C$7)*$C$6) | L54: =IF(I54="","",ROUND(I54*(1+$C$9),2)) | M54: =IF(J54="","",ROUND(J54*(1+$C$9),2)) | N54: =IF(K54="","",ROUND(K54*(1+$C$9),2)) | O54: =TRIM(IF($B54="NOT ASSIGNED","No NW part no. ","")&IFERROR(IF(INDEX(Conversion!$J$2:$J$500,MATCH($A54,Conversion!$B$2:$B$500,0))="Needs review","Conversion table: needs review. ",""),"")&IF(LEFT($E54,8)="ESTIMATE","Weight estimated. ","")&"Pricelist code BRFTP03 vs catalogue/conversion BRFTP13 - confirm with AKBO.")
A55: AKRN001-B | B55: =IFERROR(INDEX(Conversion!$C$2:$C$500,MATCH($A55,Conversion!$B$2:$B$500,0)),"NOT ASSIGNED") | C55: St.st. water gun, blue | D55: 0.813 | E55: Cat p.15 | F55: 80.068824 | G55: 71.18 | I55: =IF(F55="","",F55/$C$5*(1+$C$8)+$D55*(1+$C$7)*$C$6) | J55: =IF(G55="","",G55/$C$5*(1+$C$8)+$D55*(1+$C$7)*$C$6) | K55: =IF(H55="","",H55/$C$5*(1+$C$8)+$D55*(1+$C$7)*$C$6) | L55: =IF(I55="","",ROUND(I55*(1+$C$9),2)) | M55: =IF(J55="","",ROUND(J55*(1+$C$9),2)) | N55: =IF(K55="","",ROUND(K55*(1+$C$9),2)) | O55: =TRIM(IF($B55="NOT ASSIGNED","No NW part no. ","")&IFERROR(IF(INDEX(Conversion!$J$2:$J$500,MATCH($A55,Conversion!$B$2:$B$500,0))="Needs review","Conversion table: needs review. ",""),"")&IF(LEFT($E55,8)="ESTIMATE","Weight estimated. ","")&"")
A56: AKRN001-W | B56: =IFERROR(INDEX(Conversion!$C$2:$C$500,MATCH($A56,Conversion!$B$2:$B$500,0)),"NOT ASSIGNED") | C56: St.st. water gun, white | D56: 0.813 | E56: Cat p.15 | F56: 80.068824 | G56: 71.18 | I56: =IF(F56="","",F56/$C$5*(1+$C$8)+$D56*(1+$C$7)*$C$6) | J56: =IF(G56="","",G56/$C$5*(1+$C$8)+$D56*(1+$C$7)*$C$6) | K56: =IF(H56="","",H56/$C$5*(1+$C$8)+$D56*(1+$C$7)*$C$6) | L56: =IF(I56="","",ROUND(I56*(1+$C$9),2)) | M56: =IF(J56="","",ROUND(J56*(1+$C$9),2)) | N56: =IF(K56="","",ROUND(K56*(1+$C$9),2)) | O56: =TRIM(IF($B56="NOT ASSIGNED","No NW part no. ","")&IFERROR(IF(INDEX(Conversion!$J$2:$J$500,MATCH($A56,Conversion!$B$2:$B$500,0))="Needs review","Conversion table: needs review. ",""),"")&IF(LEFT($E56,8)="ESTIMATE","Weight estimated. ","")&"")
A57: AKRNP01-B | B57: =IFERROR(INDEX(Conversion!$C$2:$C$500,MATCH($A57,Conversion!$B$2:$B$500,0)),"NOT ASSIGNED") | C57: St.st. water gun, with trigger protection, blue | D57: 0.983 | E57: Cat p.15 | F57: 82.562832 | G57: 73.39 | I57: =IF(F57="","",F57/$C$5*(1+$C$8)+$D57*(1+$C$7)*$C$6) | J57: =IF(G57="","",G57/$C$5*(1+$C$8)+$D57*(1+$C$7)*$C$6) | K57: =IF(H57="","",H57/$C$5*(1+$C$8)+$D57*(1+$C$7)*$C$6) | L57: =IF(I57="","",ROUND(I57*(1+$C$9),2)) | M57: =IF(J57="","",ROUND(J57*(1+$C$9),2)) | N57: =IF(K57="","",ROUND(K57*(1+$C$9),2)) | O57: =TRIM(IF($B57="NOT ASSIGNED","No NW part no. ","")&IFERROR(IF(INDEX(Conversion!$J$2:$J$500,MATCH($A57,Conversion!$B$2:$B$500,0))="Needs review","Conversion table: needs review. ",""),"")&IF(LEFT($E57,8)="ESTIMATE","Weight estimated. ","")&"")
A58: AKRNP01-W | B58: =IFERROR(INDEX(Conversion!$C$2:$C$500,MATCH($A58,Conversion!$B$2:$B$500,0)),"NOT ASSIGNED") | C58: St.st. water gun, with trigger protection, white | D58: 0.983 | E58: Cat p.15 | F58: 82.562832 | G58: 73.39 | I58: =IF(F58="","",F58/$C$5*(1+$C$8)+$D58*(1+$C$7)*$C$6) | J58: =IF(G58="","",G58/$C$5*(1+$C$8)+$D58*(1+$C$7)*$C$6) | K58: =IF(H58="","",H58/$C$5*(1+$C$8)+$D58*(1+$C$7)*$C$6) | L58: =IF(I58="","",ROUND(I58*(1+$C$9),2)) | M58: =IF(J58="","",ROUND(J58*(1+$C$9),2)) | N58: =IF(K58="","",ROUND(K58*(1+$C$9),2)) | O58: =TRIM(IF($B58="NOT ASSIGNED","No NW part no. ","")&IFERROR(IF(INDEX(Conversion!$J$2:$J$500,MATCH($A58,Conversion!$B$2:$B$500,0))="Needs review","Conversion table: needs review. ",""),"")&IF(LEFT($E58,8)="ESTIMATE","Weight estimated. ","")&"")
A60: AKRHP01-R | B60: =IFERROR(INDEX(Conversion!$C$2:$C$500,MATCH($A60,Conversion!$B$2:$B$500,0)),"NOT ASSIGNED") | C60: St.st. water gun with trigger protection, Teflon/air handgrip insulation, red | D60: 0.98 | E60: Cat p.22 | F60: 91.747854 | G60: 81.55 | I60: =IF(F60="","",F60/$C$5*(1+$C$8)+$D60*(1+$C$7)*$C$6) | J60: =IF(G60="","",G60/$C$5*(1+$C$8)+$D60*(1+$C$7)*$C$6) | K60: =IF(H60="","",H60/$C$5*(1+$C$8)+$D60*(1+$C$7)*$C$6) | L60: =IF(I60="","",ROUND(I60*(1+$C$9),2)) | M60: =IF(J60="","",ROUND(J60*(1+$C$9),2)) | N60: =IF(K60="","",ROUND(K60*(1+$C$9),2)) | O60: =TRIM(IF($B60="NOT ASSIGNED","No NW part no. ","")&IFERROR(IF(INDEX(Conversion!$J$2:$J$500,MATCH($A60,Conversion!$B$2:$B$500,0))="Needs review","Conversion table: needs review. ",""),"")&IF(LEFT($E60,8)="ESTIMATE","Weight estimated. ","")&"")
A61: AKRHPB1-R | B61: =IFERROR(INDEX(Conversion!$C$2:$C$500,MATCH($A61,Conversion!$B$2:$B$500,0)),"NOT ASSIGNED") | C61: St.st. water gun, big flow, with trigger protection, Teflon/air handgrip insulation, red | D61: 0.98 | E61: Cat p.22 | F61: 91.747854 | G61: 81.55 | I61: =IF(F61="","",F61/$C$5*(1+$C$8)+$D61*(1+$C$7)*$C$6) | J61: =IF(G61="","",G61/$C$5*(1+$C$8)+$D61*(1+$C$7)*$C$6) | K61: =IF(H61="","",H61/$C$5*(1+$C$8)+$D61*(1+$C$7)*$C$6) | L61: =IF(I61="","",ROUND(I61*(1+$C$9),2)) | M61: =IF(J61="","",ROUND(J61*(1+$C$9),2)) | N61: =IF(K61="","",ROUND(K61*(1+$C$9),2)) | O61: =TRIM(IF($B61="NOT ASSIGNED","No NW part no. ","")&IFERROR(IF(INDEX(Conversion!$J$2:$J$500,MATCH($A61,Conversion!$B$2:$B$500,0))="Needs review","Conversion table: needs review. ",""),"")&IF(LEFT($E61,8)="ESTIMATE","Weight estimated. ","")&"")
...

Sheet Conversion
A1: Category | B1: AKBO Part Number | C1: Our Code | D1: Product Type | E1: Size / Dimensions / Connection | F1: Material | G1: Variant | H1: Description | I1: Source Page | J1: Status | K1: Notes
A2: Washdown / cleaning equipment | B2: AKMN011-B | C2: WD-MN011-B | D2: Wash gun | E2: Blue King, 1/2" BSP female inlet | F2: Brass HPb59-3 | H2: Wash gun, Blue King, 1/2" BSP female inlet, Brass HPb59-3 | I2: 07 - Blue King.pdf | J2: Confirmed
A3: Washdown / cleaning equipment | B3: AKMNP11-B | C3: WD-MNP11-B | D3: Wash gun | E3: Blue King, 1/2" BSP female inlet | F3: Brass HPb59-3 | G3: with trigger guard | H3: Wash gun, Blue King, 1/2" BSP female inlet, Brass HPb59-3, with trigger guard | I3: 07 - Blue King.pdf | J3: Confirmed
A4: Washdown / cleaning equipment | B4: AKMNP11-B-SW12 | C4: WD-MNP11-B-SW12 | D4: Wash gun | E4: Blue King, 1/2" BSP female inlet, with swivel | F4: Brass HPb59-3 | G4: with trigger guard and swivel | H4: Wash gun, Blue King, 1/2" BSP female inlet, with swivel, Brass HPb59-3, with trigger guard and swivel | I4: 07 - Blue King.pdf | J4: Confirmed
A5: Washdown / cleaning equipment | B5: AKRSV01-B | C5: WD-RSV01-B | D5: The Squeezer | E5: 1/2" BSP female (inlet and outlet) | F5: Stainless steel AISI 304 | G5: blue, max 40 bar / 95C | H5: The Squeezer, 1/2" BSP female (inlet and outlet), Stainless steel AISI 304, blue, max 40 bar / 95C | I5: 03 - The Squeezer.pdf | J5: Confirmed
A6: Washdown / cleaning equipment | B6: BMFT001-B | C6: WD-BMFT001-B | D6: Blue Princess | E6: 1/2" BSP female | F6: Brass HPb59-3 | G6: basic model, without trigger guard | H6: Blue Princess, 1/2" BSP female, Brass HPb59-3, basic model, without trigger guard | I6: 08 - Blue Princess.pdf | J6: Confirmed | K6: Identical spec also duplicated on page 05 (Recently Introduced) - not double counted
A7: Washdown / cleaning equipment | B7: BMFTP11-B-PRIN | C7: WD-BMFTP11-B-PRIN | D7: Blue Princess | E7: 1/2" BSP female | F7: Brass HPb59-3 | G7: with trigger guard | H7: Blue Princess, 1/2" BSP female, Brass HPb59-3, with trigger guard | I7: 08 - Blue Princess.pdf | J7: Confirmed | K7: Identical spec also duplicated on page 05
A8: Washdown / cleaning equipment | B8: BRFT003-B | C8: WD-BRFT003-B | D8: Blue Princess | E8: 1/2" BSP female | F8: 316 stainless steel (AISI 316) | G8: basic model, without trigger guard | H8: Blue Princess, 1/2" BSP female, 316 stainless steel (AISI 316), basic model, without trigger guard | I8: 08 - Blue Princess.pdf | J8: Confirmed | K8: Identical spec also duplicated on page 05
A9: Washdown / cleaning equipment | B9: BRFTP13-B-PRIN | C9: WD-BRFTP13-B-PRIN | D9: Blue Princess | E9: 1/2" BSP female | F9: 316 stainless steel (AISI 316) | G9: with trigger guard - marked NEW in catalogue | H9: Blue Princess, 1/2" BSP female, 316 stainless steel (AISI 316), with trigger guard - marked NEW in catalogue | I9: 08 - Blue Princess.pdf | J9: Confirmed | K9: Identical spec also duplicated on page 05
A10: Washdown / cleaning equipment | B10: KLMN001-BL | C10: WD-KLMN001-BL | D10: Basic brass cleaning gun | E10: 1/2" BSP female | F10: Brass | G10: black | H10: Basic brass cleaning gun, 1/2" BSP female, Brass, black | I10: 09 - Basic brass cleaning gun.pdf | J10: Confirmed
A11: Washdown / cleaning equipment | B11: KLMN001-W | C11: WD-KLMN001-W | D11: Basic brass cleaning gun | E11: 1/2" BSP female | F11: Brass | G11: white | H11: Basic brass cleaning gun, 1/2" BSP female, Brass, white | I11: 09 - Basic brass cleaning gun.pdf | J11: Confirmed
A12: Washdown / cleaning equipment | B12: KLMN001-B | C12: WD-KLMN001-B | D12: Basic brass cleaning gun | E12: 1/2" BSP female | F12: Brass | G12: blue | H12: Basic brass cleaning gun, 1/2" BSP female, Brass, blue | I12: 09 - Basic brass cleaning gun.pdf | J12: Confirmed
A13: Washdown / cleaning equipment | B13: KLMN001-G | C13: WD-KLMN001-G | D13: Basic brass cleaning gun | E13: 1/2" BSP female | F13: Brass | G13: green | H13: Basic brass cleaning gun, 1/2" BSP female, Brass, green | I13: 09 - Basic brass cleaning gun.pdf | J13: Confirmed
A14: Washdown / cleaning equipment | B14: KLMN001-R | C14: WD-KLMN001-R | D14: Basic brass cleaning gun | E14: 1/2" BSP female | F14: Brass | G14: red | H14: Basic brass cleaning gun, 1/2" BSP female, Brass, red | I14: 09 - Basic brass cleaning gun.pdf | J14: Confirmed
A15: Washdown / cleaning equipment | B15: KLMN001-Y | C15: WD-KLMN001-Y | D15: Basic brass cleaning gun | E15: 1/2" BSP female | F15: Brass | G15: yellow | H15: Basic brass cleaning gun, 1/2" BSP female, Brass, yellow | I15: 09 - Basic brass cleaning gun.pdf | J15: Confirmed
A16: Washdown / cleaning equipment | B16: AKMN001-B | C16: WD-MN001-B | D16: Brass cleaning gun (insulated trigger) | E16: 1/2" BSP female | F16: Brass HPb59-3 | G16: blue (best-seller) | H16: Brass cleaning gun (insulated trigger), 1/2" BSP female, Brass HPb59-3, blue (best-seller) | I16: 10 - Brass cleaning guns with insulated trigger.pdf | J16: Confirmed
A17: Washdown / cleaning equipment | B17: AKMN001-R | C17: WD-MN001-R | D17: Brass cleaning gun (insulated trigger) | E17: 1/2" BSP female | F17: Brass HPb59-3 | G17: red | H17: Brass cleaning gun (insulated trigger), 1/2" BSP female, Brass HPb59-3, red | I17: 10 - Brass cleaning guns with insulated trigger.pdf | J17: Confirmed
A18: Washdown / cleaning equipment | B18: AKMN001-Y | C18: WD-MN001-Y | D18: Brass cleaning gun (insulated trigger) | E18: 1/2" BSP female | F18: Brass HPb59-3 | G18: yellow | H18: Brass cleaning gun (insulated trigger), 1/2" BSP female, Brass HPb59-3, yellow | I18: 10 - Brass cleaning guns with insulated trigger.pdf | J18: Confirmed
A19: Washdown / cleaning equipment | B19: AKMN001-G | C19: WD-MN001-G | D19: Brass cleaning gun (insulated trigger) | E19: 1/2" BSP female | F19: Brass HPb59-3 | G19: green | H19: Brass cleaning gun (insulated trigger), 1/2" BSP female, Brass HPb59-3, green | I19: 10 - Brass cleaning guns with insulated trigger.pdf | J19: Confirmed
A20: Washdown / cleaning equipment | B20: AKMN001-W | C20: WD-MN001-W | D20: Brass cleaning gun (insulated trigger) | E20: 1/2" BSP female | F20: Brass HPb59-3 | G20: white | H20: Brass cleaning gun (insulated trigger), 1/2" BSP female, Brass HPb59-3, white | I20: 10 - Brass cleaning guns with insulated trigger.pdf | J20: Confirmed
A21: Washdown / cleaning equipment | B21: AKMN001-BL | C21: WD-MN001-BL | D21: Brass cleaning gun (insulated trigger) | E21: 1/2" BSP female | F21: Brass HPb59-3 | G21: black | H21: Brass cleaning gun (insulated trigger), 1/2" BSP female, Brass HPb59-3, black | I21: 10 - Brass cleaning guns with insulated trigger.pdf | J21: Confirmed
A22: Washdown / cleaning equipment | B22: AKMNP01-B | C22: WD-MNP01-B | D22: Brass cleaning gun (insulated trigger) | E22: 1/2" BSP female | F22: Brass HPb59-3 | G22: blue, with trigger guard | H22: Brass cleaning gun (insulated trigger), 1/2" BSP female, Brass HPb59-3, blue, with trigger guard | I22: 10 - Brass cleaning guns with insulated trigger.pdf | J22: Confirmed
A23: Washdown / cleaning equipment | B23: AKMNP01-B-SW12 | C23: WD-MNP01-B-SW12 | D23: Brass cleaning gun (insulated trigger) | E23: with ball bearing swivel, 1/2" BSP female | F23: Brass HPb59-3 | G23: with trigger guard and swivel | H23: Brass cleaning gun (insulated trigger), with ball bearing swivel, 1/2" BSP female, Brass HPb59-3, with trigger guard and swivel | I23: 10 - Brass cleaning guns with insulated trigger.pdf | J23: Needs review | K23: Page 2 technical-data table header spells this "AKMP01-B-SW12" (missing N) - likely a table typo, confirm before use
A24: Washdown / cleaning equipment | B24: AKMNP01-B-SW34 | C24: WD-MNP01-B-SW34 | D24: Brass cleaning gun (insulated trigger) | E24: with ball bearing swivel, 3/4" BSP female | F24: Brass HPb59-3 | G24: with trigger guard and swivel | H24: Brass cleaning gun (insulated trigger), with ball bearing swivel, 3/4" BSP female, Brass HPb59-3, with trigger guard and swivel | I24: 10 - Brass cleaning guns with insulated trigger.pdf | J24: Needs review | K24: Page 2 technical-data table header spells this "AKMP01-B-SW34" (missing N) - likely a table typo, confirm before use
A25: Washdown / cleaning equipment | B25: AKCN001-B | C25: WD-CN001-B | D25: Chrome-plated brass cleaning gun | E25: 1/2" BSP female | F25: Brass HPb59-3 + chrome layer | G25: blue | H25: Chrome-plated brass cleaning gun, 1/2" BSP female, Brass HPb59-3 + chrome layer, blue | I25: 11 - Chrome-plated brass cleaning guns.pdf | J25: Confirmed
A26: Washdown / cleaning equipment | B26: AKCNP01-B | C26: WD-CNP01-B | D26: Chrome-plated brass cleaning gun | E26: 1/2" BSP female | F26: Brass HPb59-3 + chrome layer | G26: blue, with trigger guard | H26: Chrome-plated brass cleaning gun, 1/2" BSP female, Brass HPb59-3 + chrome layer, blue, with trigger guard | I26: 11 - Chrome-plated brass cleaning guns.pdf | J26: Confirmed
A27: Washdown / cleaning equipment | B27: AKCNP01-W | C27: WD-CNP01-W | D27: Chrome-plated brass cleaning gun | E27: 1/2" BSP female | F27: Brass HPb59-3 + chrome layer | G27: white, with trigger guard | H27: Chrome-plated brass cleaning gun, 1/2" BSP female, Brass HPb59-3 + chrome layer, white, with trigger guard | I27: 11 - Chrome-plated brass cleaning guns.pdf | J27: Confirmed
A28: Washdown / cleaning equipment | B28: AKCNP01-W-U | C28: WD-CNP01-W-U | D28: Chrome-plated brass cleaning gun | E28: 1/2" NPT female | F28: Brass HPb59-3 + chrome layer | G28: white, with trigger guard | H28: Chrome-plated brass cleaning gun, 1/2" NPT female, Brass HPb59-3 + chrome layer, white, with trigger guard | I28: 11 - Chrome-plated brass cleaning guns.pdf | J28: Confirmed
A29: Washdown / cleaning equipment | B29: AKCNP01-B-SW12 | C29: WD-CNP01-B-SW12 | D29: Chrome-plated brass cleaning gun | E29: with swivel, 1/2" BSP female | F29: Brass HPb59-3 + chrome layer | G29: blue, with swivel | H29: Chrome-plated brass cleaning gun, with swivel, 1/2" BSP female, Brass HPb59-3 + chrome layer, blue, with swivel | I29: 11 - Chrome-plated brass cleaning guns.pdf | J29: Confirmed
A30: Washdown / cleaning equipment | B30: AKCNP01-W-SW12 | C30: WD-CNP01-W-SW12 | D30: Chrome-plated brass cleaning gun | E30: with swivel, brochure states 3/4" BSP female | F30: Brass HPb59-3 + chrome layer | G30: white, with swivel | H30: Chrome-plated brass cleaning gun, with swivel, brochure states 3/4" BSP female, Brass HPb59-3 + chrome layer, white, with swivel | I30: 11 - Chrome-plated brass cleaning guns.pdf | J30: Needs review | K30: Brochure states this swivel is 3/4" BSP, but the "-SW12" suffix means 1/2" everywhere else in this catalogue family (c.f. page 10 -SW12/-SW34 pattern) - likely should be AKCNP01-W-SW34; confirm with AKBO before quoting
A31: Washdown / cleaning equipment | B31: AKRN001-B | C31: WD-RN001-B | D31: Stainless steel cleaning gun (AISI 316) | E31: 1/2" BSP female | F31: Stainless steel AISI 316 | G31: blue | H31: Stainless steel cleaning gun (AISI 316), 1/2" BSP female, Stainless steel AISI 316, blue | I31: 12 - Stainless steel cleaning guns (AISI 316).pdf | J31: Confirmed
A32: Washdown / cleaning equipment | B32: AKRN001-W | C32: WD-RN001-W | D32: Stainless steel cleaning gun (AISI 316) | E32: 1/2" BSP female | F32: Stainless steel AISI 316 | G32: white | H32: Stainless steel cleaning gun (AISI 316), 1/2" BSP female, Stainless steel AISI 316, white | I32: 12 - Stainless steel cleaning guns (AISI 316).pdf | J32: Confirmed
A33: Washdown / cleaning equipment | B33: AKRB001-BL | C33: WD-RB001-BL | D33: Stainless steel cleaning gun (AISI 316), high flow | E33: 1/2" BSP female | F33: Stainless steel AISI 316 | G33: black, high flow | H33: Stainless steel cleaning gun (AISI 316), high flow, 1/2" BSP female, Stainless steel AISI 316, black, high flow | I33: 12 - Stainless steel cleaning guns (AISI 316).pdf | J33: Needs review | K33: Page 12 cross-references this as the high-flow AISI316 variant ("full spec page 16"), but page 16 (High-flow cleaning guns) only lists brass "AKMB*" numbers - no matching AKRB* found there. Confirm actual model number with AKBO
A34: Washdown / cleaning equipment | B34: AKRNP01-B | C34: WD-RNP01-B | D34: Stainless steel cleaning gun (AISI 316) | E34: 1/2" BSP female | F34: Stainless steel AISI 316 | G34: blue, with trigger guard | H34: Stainless steel cleaning gun (AISI 316), 1/2" BSP female, Stainless steel AISI 316, blue, with trigger guard | I34: 12 - Stainless steel cleaning guns (AISI 316).pdf | J34: Confirmed
A35: Washdown / cleaning equipment | B35: AKRNP01-W | C35: WD-RNP01-W | D35: Stainless steel cleaning gun (AISI 316) | E35: 1/2" BSP female | F35: Stainless steel AISI 316 | G35: white, with trigger guard | H35: Stainless steel cleaning gun (AISI 316), 1/2" BSP female, Stainless steel AISI 316, white, with trigger guard | I35: 12 - Stainless steel cleaning guns (AISI 316).pdf | J35: Confirmed
A36: Washdown / cleaning equipment | B36: AKRNP01-B-U | C36: WD-RNP01-B-U | D36: Stainless steel cleaning gun (AISI 316) | E36: 1/2" NPT female | F36: Stainless steel AISI 316 | G36: blue, with trigger guard | H36: Stainless steel cleaning gun (AISI 316), 1/2" NPT female, Stainless steel AISI 316, blue, with trigger guard | I36: 12 - Stainless steel cleaning guns (AISI 316).pdf | J36: Confirmed
A37: Washdown / cleaning equipment | B37: AKRNP01-W-U | C37: WD-RNP01-W-U | D37: Stainless steel cleaning gun (AISI 316) | E37: 1/2" NPT female | F37: Stainless steel AISI 316 | G37: white, with trigger guard | H37: Stainless steel cleaning gun (AISI 316), 1/2" NPT female, Stainless steel AISI 316, white, with trigger guard | I37: 12 - Stainless steel cleaning guns (AISI 316).pdf | J37: Confirmed
A38: Washdown / cleaning equipment | B38: AKRNP01-B-SW12 | C38: WD-RNP01-B-SW12 | D38: Stainless steel cleaning gun (AISI 316) | E38: with stainless steel swivel, 1/2" BSP female | F38: Stainless steel AISI 316 | G38: blue, with trigger guard and swivel | H38: Stainless steel cleaning gun (AISI 316), with stainless steel swivel, 1/2" BSP female, Stainless steel AISI 316, blue, with trigger guard and swivel | I38: 12 - Stainless steel cleaning guns (AISI 316).pdf | J38: Confirmed
A39: Washdown / cleaning equipment | B39: AKRNP01-W-SW12 | C39: WD-RNP01-W-SW12 | D39: Stainless steel cleaning gun (AISI 316) | E39: with stainless steel swivel, 1/2" BSP female | F39: Stainless steel AISI 316 | G39: white, with trigger guard and swivel | H39: Stainless steel cleaning gun (AISI 316), with stainless steel swivel, 1/2" BSP female, Stainless steel AISI 316, white, with trigger guard and swivel | I39: 12 - Stainless steel cleaning guns (AISI 316).pdf | J39: Confirmed
A40: Washdown / cleaning equipment | B40: AKNN001-B | C40: WD-NN001-B | D40: Lightweight cleaning gun | E40: 1/2" BSP female | F40: Plastic PA66 (fibreglass-reinforced) | G40: without trigger guard | H40: Lightweight cleaning gun, 1/2" BSP female, Plastic PA66 (fibreglass-reinforced), without trigger guard | I40: 13 - Lightweight cleaning gun.pdf | J40: Confirmed
...

Sheet Flags
A1: Items to action
A3: 1. AKBO pricelist items with no Nozzleworks part number in the conversion table
A4: AKBO code | B4: Description | C4: Nozzleworks Part No (live)
A5: BMFT001-B-PRIN | B5: Blue Princess economic brass water gun, blue with PRINCESS logo | C5: =IFERROR(INDEX(Conversion!$C$2:$C$500,MATCH($A5,Conversion!$B$2:$B$500,0)),"NOT ASSIGNED")
A6: AKMN011-B-KING | B6: Blue King superior brass water gun without trigger protection, blue with KING logo | C6: =IFERROR(INDEX(Conversion!$C$2:$C$500,MATCH($A6,Conversion!$B$2:$B$500,0)),"NOT ASSIGNED")
A7: AKMNP11-B-KING | B7: Blue King superior brass water gun with trigger protection, blue with KING logo | C7: =IFERROR(INDEX(Conversion!$C$2:$C$500,MATCH($A7,Conversion!$B$2:$B$500,0)),"NOT ASSIGNED")
A8: BRFT003-B-PRIN | B8: Blue Princess economic stainless steel water gun, blue with PRINCESS logo | C8: =IFERROR(INDEX(Conversion!$C$2:$C$500,MATCH($A8,Conversion!$B$2:$B$500,0)),"NOT ASSIGNED")
A9: BRFTP03-B-PRIN | B9: Blue Princess economic stainless steel water gun, with trigger guard and insulation trigger, bue with Princess logo | C9: =IFERROR(INDEX(Conversion!$C$2:$C$500,MATCH($A9,Conversion!$B$2:$B$500,0)),"NOT ASSIGNED")
A10: AKR001-B | B10: St, st. shower head, blue | C10: =IFERROR(INDEX(Conversion!$C$2:$C$500,MATCH($A10,Conversion!$B$2:$B$500,0)),"NOT ASSIGNED")
A11: BABTA01-B | B11: Aluminium "baby" water gun, back trigger, adapter outlet, blue | C11: =IFERROR(INDEX(Conversion!$C$2:$C$500,MATCH($A11,Conversion!$B$2:$B$500,0)),"NOT ASSIGNED")
A12: BABTNAA-B | B12: Aluminium "baby" water gun, back trigger, adapter in/output, blue | C12: =IFERROR(INDEX(Conversion!$C$2:$C$500,MATCH($A12,Conversion!$B$2:$B$500,0)),"NOT ASSIGNED")
A13: BMBTL01-B | B13: Brass "baby" water gun, back trigger, 1/2" male outlet, blue | C13: =IFERROR(INDEX(Conversion!$C$2:$C$500,MATCH($A13,Conversion!$B$2:$B$500,0)),"NOT ASSIGNED")
A14: BMBTA01-B | B14: Brass "baby" water gun, back trigger, adapter output, blue | C14: =IFERROR(INDEX(Conversion!$C$2:$C$500,MATCH($A14,Conversion!$B$2:$B$500,0)),"NOT ASSIGNED")
A15: BMBTA02-B-V | B15: Brass "baby" water gun, back trigger, adapter output, viton seals, blue | C15: =IFERROR(INDEX(Conversion!$C$2:$C$500,MATCH($A15,Conversion!$B$2:$B$500,0)),"NOT ASSIGNED")
A16: AKRSH03-W | B16: St.st. spray head black, white handgrip | C16: =IFERROR(INDEX(Conversion!$C$2:$C$500,MATCH($A16,Conversion!$B$2:$B$500,0)),"NOT ASSIGNED")
... A95: RVSW25C36-1C | B95: St.st. hose tail 25mm x 1" BSP female screw cap with conical seal, 36mm collar | C95: =IFERROR(INDEX(Conversion!$C$2:$C$500,MATCH($A95,Conversion!$B$2:$B$500,0)),"NOT ASSIGNED")
A96: 91 items at build time (column C updates as codes are added to the Conversion sheet).
A98: 2. Weights not printed in the AKBO 2026 catalogue (estimated - please confirm with AKBO)
A99: AKBO code | B99: Estimated kg | C99: Basis
A100: AKMBP01-BL | B100: 1.036 | C100: ESTIMATE - not tabulated; AKMB001-BL + trigger guard (AKMN delta)
A101: AKRB001-BL | B101: 0.84 | C101: ESTIMATE - not tabulated; taken as AKMB001-BL
A102: BABTA01-B | B102: 0.365 | C102: ESTIMATE - not in catalogue; taken as BABTLF1-BL
A103: BABTNAA-B | B103: 0.37 | C103: ESTIMATE - not in catalogue; BABTN01-B + adapters
A104: BMBTL01-B | B104: 0.65 | C104: ESTIMATE - not in catalogue; taken as BMBNN01-B
A105: BMBTA01-B | B105: 0.65 | C105: ESTIMATE - not in catalogue; taken as BMBNN01-B
A106: BMBTA02-B-V | B106: 0.65 | C106: ESTIMATE - not in catalogue; taken as BMBNN01-B
A107: AKMSHHL1-BL | B107: 0.21 | C107: ESTIMATE - AKMSHL1-B 510 g less GRIPML1-B 300 g (p.53/55)
A108: AKRSHHL1-BL | B108: 0.21 | C108: ESTIMATE - AKRSHL1-B 550 g less GRIPRL1-B 340 g (p.53/55)
A109: AKWMS01 | B109: 0.3 | C109: ESTIMATE - weight not in catalogue (p.45)
A110: AKWMM01 | B110: 0.3 | C110: ESTIMATE - weight not in catalogue (p.45)
A111: AKWML01 | B111: 0.3 | C111: ESTIMATE - weight not in catalogue (p.45)
... A184: RVSW25C36-1C | B184: 0.13 | C184: ESTIMATE - catalogue gives dimensions only (p.68-71)
A186: 3. Part-number / data queries
A187: BRFTP03-B-PRIN | C187: Pricelist code BRFTP03 vs catalogue/conversion BRFTP13 - confirm with AKBO.
A188: AKR001-B | C188: Catalogue code is AKRS001-B - confirm with AKBO.
A189: AKMBP01-BL | C189: Catalogue only lists AKMBP01-B-SWM14-3/4 (with swivel) - confirm model.
A190: AKMNP01-B-SW12 | C190: Conversion table: Page 2 technical-data table header spells this "AKMP01-B-SW12" (missing N) - likely a table typo, confirm before use
A191: AKMNP01-B-SW34 | C191: Conversion table: Page 2 technical-data table header spells this "AKMP01-B-SW34" (missing N) - likely a table typo, confirm before use
A192: AKRB001-BL | C192: Conversion table: Page 12 cross-references this as the high-flow AISI316 variant ("full spec page 16"), but page 16 (High-flow cleaning guns) only lists brass "AKMB*" numbers - no matching AKRB* found there. Confirm actual model number with AKBO
A193: AKRHP01-R | C193: Conversion table: Body text calls the base model "AKRHP01-R" but the technical-data table heads its column "AKRHP02-R" - confirm which is correct with AKBO
...
